[2025-04-26T02:30:07.858+0000] {local_task_job_runner.py:123} INFO - ::group::Pre task execution logs
[2025-04-26T02:30:07.874+0000] {taskinstance.py:2612} INFO - Dependencies all met for dep_context=non-requeueable deps ti=<TaskInstance: tesla_ETL.load_stock_prices scheduled__2025-04-25T02:30:00+00:00 [queued]>
[2025-04-26T02:30:07.882+0000] {taskinstance.py:2612} INFO - Dependencies all met for dep_context=requeueable deps ti=<TaskInstance: tesla_ETL.load_stock_prices scheduled__2025-04-25T02:30:00+00:00 [queued]>
[2025-04-26T02:30:07.883+0000] {taskinstance.py:2865} INFO - Starting attempt 1 of 1
[2025-04-26T02:30:07.894+0000] {taskinstance.py:2888} INFO - Executing <Task(_PythonDecoratedOperator): load_stock_prices> on 2025-04-25 02:30:00+00:00
[2025-04-26T02:30:07.901+0000] {logging_mixin.py:190} WARNING - /home/***/.local/lib/python3.12/site-packages/***/task/task_runner/standard_task_runner.py:70 DeprecationWarning: This process (pid=4215) is multi-threaded, use of fork() may lead to deadlocks in the child.
[2025-04-26T02:30:07.901+0000] {standard_task_runner.py:104} INFO - Running: ['***', 'tasks', 'run', 'tesla_ETL', 'load_stock_prices', 'scheduled__2025-04-25T02:30:00+00:00', '--job-id', '30', '--raw', '--subdir', 'DAGS_FOLDER/tesla_stock_etl.py', '--cfg-path', '/tmp/tmpc4may59e']
[2025-04-26T02:30:07.903+0000] {standard_task_runner.py:72} INFO - Started process 4218 to run task
[2025-04-26T02:30:07.903+0000] {standard_task_runner.py:105} INFO - Job 30: Subtask load_stock_prices
[2025-04-26T02:30:07.948+0000] {task_command.py:467} INFO - Running <TaskInstance: tesla_ETL.load_stock_prices scheduled__2025-04-25T02:30:00+00:00 [running]> on host 30114da9400b
[2025-04-26T02:30:08.093+0000] {taskinstance.py:3131} INFO - Exporting env vars: AIRFLOW_CTX_DAG_OWNER='***' AIRFLOW_CTX_DAG_ID='tesla_ETL' AIRFLOW_CTX_TASK_ID='load_stock_prices' AIRFLOW_CTX_EXECUTION_DATE='2025-04-25T02:30:00+00:00' AIRFLOW_CTX_TRY_NUMBER='1' AIRFLOW_CTX_DAG_RUN_ID='scheduled__2025-04-25T02:30:00+00:00'
[2025-04-26T02:30:08.095+0000] {taskinstance.py:731} INFO - ::endgroup::
[2025-04-26T02:30:08.328+0000] {cursor.py:1156} INFO - Number of results in first chunk: 1
[2025-04-26T02:30:08.463+0000] {cursor.py:1156} INFO - Number of results in first chunk: 1
[2025-04-26T03:19:18.561+0000] {job.py:229} INFO - Heartbeat recovered after 2734.18 seconds
[2025-04-26T03:43:56.429+0000] {job.py:229} INFO - Heartbeat recovered after 1112.90 seconds
[2025-04-26T03:44:20.848+0000] {job.py:229} INFO - Heartbeat recovered after 24.48 seconds
[2025-04-26T03:44:47.336+0000] {cursor.py:1156} INFO - Number of results in first chunk: 1
[2025-04-26T03:44:47.406+0000] {logging_mixin.py:190} INFO - ("Connection broken: InvalidChunkLength(got length b'', 0 bytes read)", InvalidChunkLength(got length b'', 0 bytes read))
[2025-04-26T03:44:47.467+0000] {taskinstance.py:3310} ERROR - Task failed with exception
Traceback (most recent call last):
  File "/home/airflow/.local/lib/python3.12/site-packages/snowflake/connector/vendored/urllib3/response.py", line 761, in _update_chunk_length
    self.chunk_left = int(line, 16)
                      ^^^^^^^^^^^^^
ValueError: invalid literal for int() with base 16: b''

During handling of the above exception, another exception occurred:

Traceback (most recent call last):
  File "/home/airflow/.local/lib/python3.12/site-packages/snowflake/connector/vendored/urllib3/response.py", line 444, in _error_catcher
    yield
  File "/home/airflow/.local/lib/python3.12/site-packages/snowflake/connector/vendored/urllib3/response.py", line 828, in read_chunked
    self._update_chunk_length()
  File "/home/airflow/.local/lib/python3.12/site-packages/snowflake/connector/vendored/urllib3/response.py", line 765, in _update_chunk_length
    raise InvalidChunkLength(self, line)
snowflake.connector.vendored.urllib3.exceptions.InvalidChunkLength: InvalidChunkLength(got length b'', 0 bytes read)

During handling of the above exception, another exception occurred:

Traceback (most recent call last):
  File "/home/airflow/.local/lib/python3.12/site-packages/snowflake/connector/vendored/requests/models.py", line 816, in generate
    yield from self.raw.stream(chunk_size, decode_content=True)
  File "/home/airflow/.local/lib/python3.12/site-packages/snowflake/connector/vendored/urllib3/response.py", line 624, in stream
    for line in self.read_chunked(amt, decode_content=decode_content):
                ^^^^^^^^^^^^^^^^^^^^^^^^^^^^^^^^^^^^^^^^^^^^^^^^^^^^^
  File "/home/airflow/.local/lib/python3.12/site-packages/snowflake/connector/vendored/urllib3/response.py", line 816, in read_chunked
    with self._error_catcher():
  File "/usr/local/lib/python3.12/contextlib.py", line 158, in __exit__
    self.gen.throw(value)
  File "/home/airflow/.local/lib/python3.12/site-packages/snowflake/connector/vendored/urllib3/response.py", line 461, in _error_catcher
    raise ProtocolError("Connection broken: %r" % e, e)
snowflake.connector.vendored.urllib3.exceptions.ProtocolError: ("Connection broken: InvalidChunkLength(got length b'', 0 bytes read)", InvalidChunkLength(got length b'', 0 bytes read))

During handling of the above exception, another exception occurred:

Traceback (most recent call last):
  File "/home/airflow/.local/lib/python3.12/site-packages/airflow/models/taskinstance.py", line 767, in _execute_task
    result = _execute_callable(context=context, **execute_callable_kwargs)
             ^^^^^^^^^^^^^^^^^^^^^^^^^^^^^^^^^^^^^^^^^^^^^^^^^^^^^^^^^^^^^
  File "/home/airflow/.local/lib/python3.12/site-packages/airflow/models/taskinstance.py", line 733, in _execute_callable
    return ExecutionCallableRunner(
           ^^^^^^^^^^^^^^^^^^^^^^^^
  File "/home/airflow/.local/lib/python3.12/site-packages/airflow/utils/operator_helpers.py", line 252, in run
    return self.func(*args, **kwargs)
           ^^^^^^^^^^^^^^^^^^^^^^^^^^
  File "/home/airflow/.local/lib/python3.12/site-packages/airflow/models/baseoperator.py", line 406, in wrapper
    return func(self, *args, **kwargs)
           ^^^^^^^^^^^^^^^^^^^^^^^^^^^
  File "/home/airflow/.local/lib/python3.12/site-packages/airflow/decorators/base.py", line 266, in execute
    return_value = super().execute(context)
                   ^^^^^^^^^^^^^^^^^^^^^^^^
  File "/home/airflow/.local/lib/python3.12/site-packages/airflow/models/baseoperator.py", line 406, in wrapper
    return func(self, *args, **kwargs)
           ^^^^^^^^^^^^^^^^^^^^^^^^^^^
  File "/home/airflow/.local/lib/python3.12/site-packages/airflow/operators/python.py", line 238, in execute
    return_value = self.execute_callable()
                   ^^^^^^^^^^^^^^^^^^^^^^^
  File "/home/airflow/.local/lib/python3.12/site-packages/airflow/operators/python.py", line 256, in execute_callable
    return runner.run(*self.op_args, **self.op_kwargs)
           ^^^^^^^^^^^^^^^^^^^^^^^^^^^^^^^^^^^^^^^^^^^
  File "/home/airflow/.local/lib/python3.12/site-packages/airflow/utils/operator_helpers.py", line 252, in run
    return self.func(*args, **kwargs)
           ^^^^^^^^^^^^^^^^^^^^^^^^^^
  File "/opt/airflow/dags/tesla_stock_etl.py", line 75, in load_stock_prices
    raise e
  File "/opt/airflow/dags/tesla_stock_etl.py", line 70, in load_stock_prices
    cur.execute(sql)
  File "/home/airflow/.local/lib/python3.12/site-packages/snowflake/connector/cursor.py", line 984, in execute
    ret = self._execute_helper(query, **kwargs)
          ^^^^^^^^^^^^^^^^^^^^^^^^^^^^^^^^^^^^^
  File "/home/airflow/.local/lib/python3.12/site-packages/snowflake/connector/cursor.py", line 695, in _execute_helper
    ret = self._connection.cmd_query(
          ^^^^^^^^^^^^^^^^^^^^^^^^^^^
  File "/home/airflow/.local/lib/python3.12/site-packages/snowflake/connector/connection.py", line 1350, in cmd_query
    ret = self.rest.request(
          ^^^^^^^^^^^^^^^^^^
  File "/home/airflow/.local/lib/python3.12/site-packages/snowflake/connector/network.py", line 491, in request
    return self._post_request(
           ^^^^^^^^^^^^^^^^^^^
  File "/home/airflow/.local/lib/python3.12/site-packages/snowflake/connector/network.py", line 739, in _post_request
    ret = self.fetch(
          ^^^^^^^^^^^
  File "/home/airflow/.local/lib/python3.12/site-packages/snowflake/connector/network.py", line 854, in fetch
    ret = self._request_exec_wrapper(
          ^^^^^^^^^^^^^^^^^^^^^^^^^^^
  File "/home/airflow/.local/lib/python3.12/site-packages/snowflake/connector/network.py", line 971, in _request_exec_wrapper
    raise e
  File "/home/airflow/.local/lib/python3.12/site-packages/snowflake/connector/network.py", line 896, in _request_exec_wrapper
    return_object = self._request_exec(
                    ^^^^^^^^^^^^^^^^^^^
  File "/home/airflow/.local/lib/python3.12/site-packages/snowflake/connector/network.py", line 1156, in _request_exec
    raise err
  File "/home/airflow/.local/lib/python3.12/site-packages/snowflake/connector/network.py", line 1059, in _request_exec
    raw_ret = session.request(
              ^^^^^^^^^^^^^^^^
  File "/home/airflow/.local/lib/python3.12/site-packages/snowflake/connector/vendored/requests/sessions.py", line 589, in request
    resp = self.send(prep, **send_kwargs)
           ^^^^^^^^^^^^^^^^^^^^^^^^^^^^^^
  File "/home/airflow/.local/lib/python3.12/site-packages/snowflake/connector/vendored/requests/sessions.py", line 747, in send
    r.content
  File "/home/airflow/.local/lib/python3.12/site-packages/snowflake/connector/vendored/requests/models.py", line 899, in content
    self._content = b"".join(self.iter_content(CONTENT_CHUNK_SIZE)) or b""
                    ^^^^^^^^^^^^^^^^^^^^^^^^^^^^^^^^^^^^^^^^^^^^^^^
  File "/home/airflow/.local/lib/python3.12/site-packages/snowflake/connector/vendored/requests/models.py", line 818, in generate
    raise ChunkedEncodingError(e)
snowflake.connector.vendored.requests.exceptions.ChunkedEncodingError: ("Connection broken: InvalidChunkLength(got length b'', 0 bytes read)", InvalidChunkLength(got length b'', 0 bytes read))
[2025-04-26T03:44:47.743+0000] {taskinstance.py:1225} INFO - Marking task as FAILED. dag_id=tesla_ETL, task_id=load_stock_prices, run_id=scheduled__2025-04-25T02:30:00+00:00, execution_date=20250425T023000, start_date=20250426T023007, end_date=20250426T034447
[2025-04-26T03:44:47.919+0000] {taskinstance.py:340} INFO - ::group::Post task execution logs
[2025-04-26T03:44:47.934+0000] {standard_task_runner.py:124} ERROR - Failed to execute job 30 for task load_stock_prices (("Connection broken: InvalidChunkLength(got length b'', 0 bytes read)", InvalidChunkLength(got length b'', 0 bytes read)); 4218)
Traceback (most recent call last):
  File "/home/airflow/.local/lib/python3.12/site-packages/snowflake/connector/vendored/urllib3/response.py", line 761, in _update_chunk_length
    self.chunk_left = int(line, 16)
                      ^^^^^^^^^^^^^
ValueError: invalid literal for int() with base 16: b''

During handling of the above exception, another exception occurred:

Traceback (most recent call last):
  File "/home/airflow/.local/lib/python3.12/site-packages/snowflake/connector/vendored/urllib3/response.py", line 444, in _error_catcher
    yield
  File "/home/airflow/.local/lib/python3.12/site-packages/snowflake/connector/vendored/urllib3/response.py", line 828, in read_chunked
    self._update_chunk_length()
  File "/home/airflow/.local/lib/python3.12/site-packages/snowflake/connector/vendored/urllib3/response.py", line 765, in _update_chunk_length
    raise InvalidChunkLength(self, line)
snowflake.connector.vendored.urllib3.exceptions.InvalidChunkLength: InvalidChunkLength(got length b'', 0 bytes read)

During handling of the above exception, another exception occurred:

Traceback (most recent call last):
  File "/home/airflow/.local/lib/python3.12/site-packages/snowflake/connector/vendored/requests/models.py", line 816, in generate
    yield from self.raw.stream(chunk_size, decode_content=True)
  File "/home/airflow/.local/lib/python3.12/site-packages/snowflake/connector/vendored/urllib3/response.py", line 624, in stream
    for line in self.read_chunked(amt, decode_content=decode_content):
                ^^^^^^^^^^^^^^^^^^^^^^^^^^^^^^^^^^^^^^^^^^^^^^^^^^^^^
  File "/home/airflow/.local/lib/python3.12/site-packages/snowflake/connector/vendored/urllib3/response.py", line 816, in read_chunked
    with self._error_catcher():
  File "/usr/local/lib/python3.12/contextlib.py", line 158, in __exit__
    self.gen.throw(value)
  File "/home/airflow/.local/lib/python3.12/site-packages/snowflake/connector/vendored/urllib3/response.py", line 461, in _error_catcher
    raise ProtocolError("Connection broken: %r" % e, e)
snowflake.connector.vendored.urllib3.exceptions.ProtocolError: ("Connection broken: InvalidChunkLength(got length b'', 0 bytes read)", InvalidChunkLength(got length b'', 0 bytes read))

During handling of the above exception, another exception occurred:

Traceback (most recent call last):
  File "/home/airflow/.local/lib/python3.12/site-packages/airflow/task/task_runner/standard_task_runner.py", line 117, in _start_by_fork
    ret = args.func(args, dag=self.dag)
          ^^^^^^^^^^^^^^^^^^^^^^^^^^^^^
  File "/home/airflow/.local/lib/python3.12/site-packages/airflow/cli/cli_config.py", line 49, in command
    return func(*args, **kwargs)
           ^^^^^^^^^^^^^^^^^^^^^
  File "/home/airflow/.local/lib/python3.12/site-packages/airflow/utils/cli.py", line 115, in wrapper
    return f(*args, **kwargs)
           ^^^^^^^^^^^^^^^^^^
  File "/home/airflow/.local/lib/python3.12/site-packages/airflow/cli/commands/task_command.py", line 483, in task_run
    task_return_code = _run_task_by_selected_method(args, _dag, ti)
                       ^^^^^^^^^^^^^^^^^^^^^^^^^^^^^^^^^^^^^^^^^^^^
  File "/home/airflow/.local/lib/python3.12/site-packages/airflow/cli/commands/task_command.py", line 256, in _run_task_by_selected_method
    return _run_raw_task(args, ti)
           ^^^^^^^^^^^^^^^^^^^^^^^
  File "/home/airflow/.local/lib/python3.12/site-packages/airflow/cli/commands/task_command.py", line 341, in _run_raw_task
    return ti._run_raw_task(
           ^^^^^^^^^^^^^^^^^
  File "/home/airflow/.local/lib/python3.12/site-packages/airflow/utils/session.py", line 97, in wrapper
    return func(*args, session=session, **kwargs)
           ^^^^^^^^^^^^^^^^^^^^^^^^^^^^^^^^^^^^^^
  File "/home/airflow/.local/lib/python3.12/site-packages/airflow/models/taskinstance.py", line 3004, in _run_raw_task
    return _run_raw_task(
           ^^^^^^^^^^^^^^
  File "/home/airflow/.local/lib/python3.12/site-packages/airflow/models/taskinstance.py", line 273, in _run_raw_task
    TaskInstance._execute_task_with_callbacks(
  File "/home/airflow/.local/lib/python3.12/site-packages/airflow/models/taskinstance.py", line 3158, in _execute_task_with_callbacks
    result = self._execute_task(context, task_orig)
             ^^^^^^^^^^^^^^^^^^^^^^^^^^^^^^^^^^^^^^
  File "/home/airflow/.local/lib/python3.12/site-packages/airflow/models/taskinstance.py", line 3182, in _execute_task
    return _execute_task(self, context, task_orig)
           ^^^^^^^^^^^^^^^^^^^^^^^^^^^^^^^^^^^^^^^
  File "/home/airflow/.local/lib/python3.12/site-packages/airflow/models/taskinstance.py", line 767, in _execute_task
    result = _execute_callable(context=context, **execute_callable_kwargs)
             ^^^^^^^^^^^^^^^^^^^^^^^^^^^^^^^^^^^^^^^^^^^^^^^^^^^^^^^^^^^^^
  File "/home/airflow/.local/lib/python3.12/site-packages/airflow/models/taskinstance.py", line 733, in _execute_callable
    return ExecutionCallableRunner(
           ^^^^^^^^^^^^^^^^^^^^^^^^
  File "/home/airflow/.local/lib/python3.12/site-packages/airflow/utils/operator_helpers.py", line 252, in run
    return self.func(*args, **kwargs)
           ^^^^^^^^^^^^^^^^^^^^^^^^^^
  File "/home/airflow/.local/lib/python3.12/site-packages/airflow/models/baseoperator.py", line 406, in wrapper
    return func(self, *args, **kwargs)
           ^^^^^^^^^^^^^^^^^^^^^^^^^^^
  File "/home/airflow/.local/lib/python3.12/site-packages/airflow/decorators/base.py", line 266, in execute
    return_value = super().execute(context)
                   ^^^^^^^^^^^^^^^^^^^^^^^^
  File "/home/airflow/.local/lib/python3.12/site-packages/airflow/models/baseoperator.py", line 406, in wrapper
    return func(self, *args, **kwargs)
           ^^^^^^^^^^^^^^^^^^^^^^^^^^^
  File "/home/airflow/.local/lib/python3.12/site-packages/airflow/operators/python.py", line 238, in execute
    return_value = self.execute_callable()
                   ^^^^^^^^^^^^^^^^^^^^^^^
  File "/home/airflow/.local/lib/python3.12/site-packages/airflow/operators/python.py", line 256, in execute_callable
    return runner.run(*self.op_args, **self.op_kwargs)
           ^^^^^^^^^^^^^^^^^^^^^^^^^^^^^^^^^^^^^^^^^^^
  File "/home/airflow/.local/lib/python3.12/site-packages/airflow/utils/operator_helpers.py", line 252, in run
    return self.func(*args, **kwargs)
           ^^^^^^^^^^^^^^^^^^^^^^^^^^
  File "/opt/airflow/dags/tesla_stock_etl.py", line 75, in load_stock_prices
    raise e
  File "/opt/airflow/dags/tesla_stock_etl.py", line 70, in load_stock_prices
    cur.execute(sql)
  File "/home/airflow/.local/lib/python3.12/site-packages/snowflake/connector/cursor.py", line 984, in execute
    ret = self._execute_helper(query, **kwargs)
          ^^^^^^^^^^^^^^^^^^^^^^^^^^^^^^^^^^^^^
  File "/home/airflow/.local/lib/python3.12/site-packages/snowflake/connector/cursor.py", line 695, in _execute_helper
    ret = self._connection.cmd_query(
          ^^^^^^^^^^^^^^^^^^^^^^^^^^^
  File "/home/airflow/.local/lib/python3.12/site-packages/snowflake/connector/connection.py", line 1350, in cmd_query
    ret = self.rest.request(
          ^^^^^^^^^^^^^^^^^^
  File "/home/airflow/.local/lib/python3.12/site-packages/snowflake/connector/network.py", line 491, in request
    return self._post_request(
           ^^^^^^^^^^^^^^^^^^^
  File "/home/airflow/.local/lib/python3.12/site-packages/snowflake/connector/network.py", line 739, in _post_request
    ret = self.fetch(
          ^^^^^^^^^^^
  File "/home/airflow/.local/lib/python3.12/site-packages/snowflake/connector/network.py", line 854, in fetch
    ret = self._request_exec_wrapper(
          ^^^^^^^^^^^^^^^^^^^^^^^^^^^
  File "/home/airflow/.local/lib/python3.12/site-packages/snowflake/connector/network.py", line 971, in _request_exec_wrapper
    raise e
  File "/home/airflow/.local/lib/python3.12/site-packages/snowflake/connector/network.py", line 896, in _request_exec_wrapper
    return_object = self._request_exec(
                    ^^^^^^^^^^^^^^^^^^^
  File "/home/airflow/.local/lib/python3.12/site-packages/snowflake/connector/network.py", line 1156, in _request_exec
    raise err
  File "/home/airflow/.local/lib/python3.12/site-packages/snowflake/connector/network.py", line 1059, in _request_exec
    raw_ret = session.request(
              ^^^^^^^^^^^^^^^^
  File "/home/airflow/.local/lib/python3.12/site-packages/snowflake/connector/vendored/requests/sessions.py", line 589, in request
    resp = self.send(prep, **send_kwargs)
           ^^^^^^^^^^^^^^^^^^^^^^^^^^^^^^
  File "/home/airflow/.local/lib/python3.12/site-packages/snowflake/connector/vendored/requests/sessions.py", line 747, in send
    r.content
  File "/home/airflow/.local/lib/python3.12/site-packages/snowflake/connector/vendored/requests/models.py", line 899, in content
    self._content = b"".join(self.iter_content(CONTENT_CHUNK_SIZE)) or b""
                    ^^^^^^^^^^^^^^^^^^^^^^^^^^^^^^^^^^^^^^^^^^^^^^^
  File "/home/airflow/.local/lib/python3.12/site-packages/snowflake/connector/vendored/requests/models.py", line 818, in generate
    raise ChunkedEncodingError(e)
snowflake.connector.vendored.requests.exceptions.ChunkedEncodingError: ("Connection broken: InvalidChunkLength(got length b'', 0 bytes read)", InvalidChunkLength(got length b'', 0 bytes read))
[2025-04-26T03:44:48.041+0000] {local_task_job_runner.py:266} INFO - Task exited with return code 1
[2025-04-26T03:44:48.148+0000] {taskinstance.py:3925} ERROR - Error scheduling downstream tasks. Skipping it as this is entirely optional optimisation. There might be various reasons for it, please take a look at the stack trace to figure out if the root cause can be diagnosed and fixed. See the issue https://github.com/apache/***/issues/39717 for details and an example problem. If you would like to get help in solving root cause, open discussion with all details with your managed service support or in Airflow repository.
Traceback (most recent call last):
  File "/home/airflow/.local/lib/python3.12/site-packages/airflow/models/taskinstance.py", line 3921, in schedule_downstream_tasks
    return TaskInstance._schedule_downstream_tasks(
           ^^^^^^^^^^^^^^^^^^^^^^^^^^^^^^^^^^^^^^^^
  File "/home/airflow/.local/lib/python3.12/site-packages/airflow/utils/session.py", line 94, in wrapper
    return func(*args, **kwargs)
           ^^^^^^^^^^^^^^^^^^^^^
  File "/home/airflow/.local/lib/python3.12/site-packages/airflow/models/taskinstance.py", line 3870, in _schedule_downstream_tasks
    partial_dag = task.dag.partial_subset(
                  ^^^^^^^^^^^^^^^^^^^^^^^^
  File "/home/airflow/.local/lib/python3.12/site-packages/airflow/models/dag.py", line 2664, in partial_subset
    t.task_id: _deepcopy_task(t)
               ^^^^^^^^^^^^^^^^^
  File "/home/airflow/.local/lib/python3.12/site-packages/airflow/models/dag.py", line 2661, in _deepcopy_task
    return copy.deepcopy(t, memo)
           ^^^^^^^^^^^^^^^^^^^^^^
  File "/usr/local/lib/python3.12/copy.py", line 143, in deepcopy
    y = copier(memo)
        ^^^^^^^^^^^^
  File "/home/airflow/.local/lib/python3.12/site-packages/airflow/models/baseoperator.py", line 1388, in __deepcopy__
    setattr(result, k, copy.deepcopy(v, memo))
                       ^^^^^^^^^^^^^^^^^^^^^^
  File "/usr/local/lib/python3.12/copy.py", line 136, in deepcopy
    y = copier(x, memo)
        ^^^^^^^^^^^^^^^
  File "/usr/local/lib/python3.12/copy.py", line 221, in _deepcopy_dict
    y[deepcopy(key, memo)] = deepcopy(value, memo)
                             ^^^^^^^^^^^^^^^^^^^^^
  File "/usr/local/lib/python3.12/copy.py", line 136, in deepcopy
    y = copier(x, memo)
        ^^^^^^^^^^^^^^^
  File "/usr/local/lib/python3.12/copy.py", line 201, in _deepcopy_tuple
    y = [deepcopy(a, memo) for a in x]
         ^^^^^^^^^^^^^^^^^
  File "/usr/local/lib/python3.12/copy.py", line 162, in deepcopy
    y = _reconstruct(x, memo, *rv)
        ^^^^^^^^^^^^^^^^^^^^^^^^^^
  File "/usr/local/lib/python3.12/copy.py", line 259, in _reconstruct
    state = deepcopy(state, memo)
            ^^^^^^^^^^^^^^^^^^^^^
  File "/usr/local/lib/python3.12/copy.py", line 136, in deepcopy
    y = copier(x, memo)
        ^^^^^^^^^^^^^^^
  File "/usr/local/lib/python3.12/copy.py", line 221, in _deepcopy_dict
    y[deepcopy(key, memo)] = deepcopy(value, memo)
                             ^^^^^^^^^^^^^^^^^^^^^
  File "/usr/local/lib/python3.12/copy.py", line 143, in deepcopy
    y = copier(memo)
        ^^^^^^^^^^^^
  File "/home/airflow/.local/lib/python3.12/site-packages/airflow/models/baseoperator.py", line 1388, in __deepcopy__
    setattr(result, k, copy.deepcopy(v, memo))
                       ^^^^^^^^^^^^^^^^^^^^^^
  File "/usr/local/lib/python3.12/copy.py", line 136, in deepcopy
    y = copier(x, memo)
        ^^^^^^^^^^^^^^^
  File "/usr/local/lib/python3.12/copy.py", line 221, in _deepcopy_dict
    y[deepcopy(key, memo)] = deepcopy(value, memo)
                             ^^^^^^^^^^^^^^^^^^^^^
  File "/usr/local/lib/python3.12/copy.py", line 136, in deepcopy
    y = copier(x, memo)
        ^^^^^^^^^^^^^^^
  File "/usr/local/lib/python3.12/copy.py", line 201, in _deepcopy_tuple
    y = [deepcopy(a, memo) for a in x]
         ^^^^^^^^^^^^^^^^^
  File "/usr/local/lib/python3.12/copy.py", line 162, in deepcopy
    y = _reconstruct(x, memo, *rv)
        ^^^^^^^^^^^^^^^^^^^^^^^^^^
  File "/usr/local/lib/python3.12/copy.py", line 259, in _reconstruct
    state = deepcopy(state, memo)
            ^^^^^^^^^^^^^^^^^^^^^
  File "/usr/local/lib/python3.12/copy.py", line 136, in deepcopy
    y = copier(x, memo)
        ^^^^^^^^^^^^^^^
  File "/usr/local/lib/python3.12/copy.py", line 221, in _deepcopy_dict
    y[deepcopy(key, memo)] = deepcopy(value, memo)
                             ^^^^^^^^^^^^^^^^^^^^^
  File "/usr/local/lib/python3.12/copy.py", line 162, in deepcopy
    y = _reconstruct(x, memo, *rv)
        ^^^^^^^^^^^^^^^^^^^^^^^^^^
  File "/usr/local/lib/python3.12/copy.py", line 259, in _reconstruct
    state = deepcopy(state, memo)
            ^^^^^^^^^^^^^^^^^^^^^
  File "/usr/local/lib/python3.12/copy.py", line 136, in deepcopy
    y = copier(x, memo)
        ^^^^^^^^^^^^^^^
  File "/usr/local/lib/python3.12/copy.py", line 221, in _deepcopy_dict
    y[deepcopy(key, memo)] = deepcopy(value, memo)
                             ^^^^^^^^^^^^^^^^^^^^^
  File "/usr/local/lib/python3.12/copy.py", line 151, in deepcopy
    rv = reductor(4)
         ^^^^^^^^^^^
TypeError: cannot pickle '_thread.lock' object
[2025-04-26T03:44:48.207+0000] {local_task_job_runner.py:245} INFO - ::endgroup::
