[2025-04-29T03:01:05.970+0000] {local_task_job_runner.py:123} INFO - ::group::Pre task execution logs
[2025-04-29T03:01:05.993+0000] {taskinstance.py:2612} INFO - Dependencies all met for dep_context=non-requeueable deps ti=<TaskInstance: tesla_stock_sentiment_final_etl.load_sentiment_data_to_snowflake manual__2025-04-29T03:01:01.458348+00:00 [queued]>
[2025-04-29T03:01:06.005+0000] {taskinstance.py:2612} INFO - Dependencies all met for dep_context=requeueable deps ti=<TaskInstance: tesla_stock_sentiment_final_etl.load_sentiment_data_to_snowflake manual__2025-04-29T03:01:01.458348+00:00 [queued]>
[2025-04-29T03:01:06.006+0000] {taskinstance.py:2865} INFO - Starting attempt 1 of 1
[2025-04-29T03:01:06.022+0000] {taskinstance.py:2888} INFO - Executing <Task(_PythonDecoratedOperator): load_sentiment_data_to_snowflake> on 2025-04-29 03:01:01.458348+00:00
[2025-04-29T03:01:06.048+0000] {logging_mixin.py:190} WARNING - /home/***/.local/lib/python3.12/site-packages/***/task/task_runner/standard_task_runner.py:70 DeprecationWarning: This process (pid=5498) is multi-threaded, use of fork() may lead to deadlocks in the child.
[2025-04-29T03:01:06.051+0000] {standard_task_runner.py:72} INFO - Started process 5508 to run task
[2025-04-29T03:01:06.050+0000] {standard_task_runner.py:104} INFO - Running: ['***', 'tasks', 'run', 'tesla_stock_sentiment_final_etl', 'load_sentiment_data_to_snowflake', 'manual__2025-04-29T03:01:01.458348+00:00', '--job-id', '67', '--raw', '--subdir', 'DAGS_FOLDER/tesla_stock_etl.py', '--cfg-path', '/tmp/tmpr8n9lb0w']
[2025-04-29T03:01:06.053+0000] {standard_task_runner.py:105} INFO - Job 67: Subtask load_sentiment_data_to_snowflake
[2025-04-29T03:01:06.118+0000] {task_command.py:467} INFO - Running <TaskInstance: tesla_stock_sentiment_final_etl.load_sentiment_data_to_snowflake manual__2025-04-29T03:01:01.458348+00:00 [running]> on host 5891a65dc7e9
[2025-04-29T03:01:06.207+0000] {taskinstance.py:3131} INFO - Exporting env vars: AIRFLOW_CTX_DAG_OWNER='***' AIRFLOW_CTX_DAG_ID='tesla_stock_sentiment_final_etl' AIRFLOW_CTX_TASK_ID='load_sentiment_data_to_snowflake' AIRFLOW_CTX_EXECUTION_DATE='2025-04-29T03:01:01.458348+00:00' AIRFLOW_CTX_TRY_NUMBER='1' AIRFLOW_CTX_DAG_RUN_ID='manual__2025-04-29T03:01:01.458348+00:00'
[2025-04-29T03:01:06.209+0000] {taskinstance.py:731} INFO - ::endgroup::
[2025-04-29T03:01:06.517+0000] {cursor.py:1156} INFO - Number of results in first chunk: 1
[2025-04-29T03:01:06.677+0000] {cursor.py:1156} INFO - Number of results in first chunk: 1
[2025-04-29T03:13:14.655+0000] {connectionpool.py:824} WARNING - Retrying (Retry(total=0, connect=None, read=None, redirect=None, status=None)) after connection broken by 'ReadTimeoutError("HTTPSConnectionPool(host='oweegxt-gvb74384.snowflakecomputing.com', port=443): Read timed out. (read timeout=60)")': /queries/01bc011f-0305-165e-0008-027b00012b2a/result?request_guid=249e8da5-0091-4485-b459-c0dfafd4ab55
[2025-04-29T03:13:38.556+0000] {cursor.py:1156} INFO - Number of results in first chunk: 1
[2025-04-29T03:13:38.564+0000] {logging_mixin.py:190} INFO - âœ… Sentiment data loaded into dev.raw.tesla_tweet_data (full refresh).
[2025-04-29T03:13:38.569+0000] {python.py:240} INFO - Done. Returned value was: None
[2025-04-29T03:13:38.669+0000] {taskinstance.py:340} INFO - ::group::Post task execution logs
[2025-04-29T03:13:38.672+0000] {taskinstance.py:352} INFO - Marking task as SUCCESS. dag_id=tesla_stock_sentiment_final_etl, task_id=load_sentiment_data_to_snowflake, run_id=manual__2025-04-29T03:01:01.458348+00:00, execution_date=20250429T030101, start_date=20250429T030105, end_date=20250429T031338
[2025-04-29T03:13:38.761+0000] {local_task_job_runner.py:266} INFO - Task exited with return code 0
[2025-04-29T03:13:38.790+0000] {taskinstance.py:3925} ERROR - Error scheduling downstream tasks. Skipping it as this is entirely optional optimisation. There might be various reasons for it, please take a look at the stack trace to figure out if the root cause can be diagnosed and fixed. See the issue https://github.com/apache/***/issues/39717 for details and an example problem. If you would like to get help in solving root cause, open discussion with all details with your managed service support or in Airflow repository.
Traceback (most recent call last):
  File "/home/airflow/.local/lib/python3.12/site-packages/airflow/models/taskinstance.py", line 3921, in schedule_downstream_tasks
    return TaskInstance._schedule_downstream_tasks(
           ^^^^^^^^^^^^^^^^^^^^^^^^^^^^^^^^^^^^^^^^
  File "/home/airflow/.local/lib/python3.12/site-packages/airflow/utils/session.py", line 94, in wrapper
    return func(*args, **kwargs)
           ^^^^^^^^^^^^^^^^^^^^^
  File "/home/airflow/.local/lib/python3.12/site-packages/airflow/models/taskinstance.py", line 3870, in _schedule_downstream_tasks
    partial_dag = task.dag.partial_subset(
                  ^^^^^^^^^^^^^^^^^^^^^^^^
  File "/home/airflow/.local/lib/python3.12/site-packages/airflow/models/dag.py", line 2664, in partial_subset
    t.task_id: _deepcopy_task(t)
               ^^^^^^^^^^^^^^^^^
  File "/home/airflow/.local/lib/python3.12/site-packages/airflow/models/dag.py", line 2661, in _deepcopy_task
    return copy.deepcopy(t, memo)
           ^^^^^^^^^^^^^^^^^^^^^^
  File "/usr/local/lib/python3.12/copy.py", line 143, in deepcopy
    y = copier(memo)
        ^^^^^^^^^^^^
  File "/home/airflow/.local/lib/python3.12/site-packages/airflow/models/baseoperator.py", line 1388, in __deepcopy__
    setattr(result, k, copy.deepcopy(v, memo))
                       ^^^^^^^^^^^^^^^^^^^^^^
  File "/usr/local/lib/python3.12/copy.py", line 136, in deepcopy
    y = copier(x, memo)
        ^^^^^^^^^^^^^^^
  File "/usr/local/lib/python3.12/copy.py", line 221, in _deepcopy_dict
    y[deepcopy(key, memo)] = deepcopy(value, memo)
                             ^^^^^^^^^^^^^^^^^^^^^
  File "/usr/local/lib/python3.12/copy.py", line 136, in deepcopy
    y = copier(x, memo)
        ^^^^^^^^^^^^^^^
  File "/usr/local/lib/python3.12/copy.py", line 201, in _deepcopy_tuple
    y = [deepcopy(a, memo) for a in x]
         ^^^^^^^^^^^^^^^^^
  File "/usr/local/lib/python3.12/copy.py", line 162, in deepcopy
    y = _reconstruct(x, memo, *rv)
        ^^^^^^^^^^^^^^^^^^^^^^^^^^
  File "/usr/local/lib/python3.12/copy.py", line 259, in _reconstruct
    state = deepcopy(state, memo)
            ^^^^^^^^^^^^^^^^^^^^^
  File "/usr/local/lib/python3.12/copy.py", line 136, in deepcopy
    y = copier(x, memo)
        ^^^^^^^^^^^^^^^
  File "/usr/local/lib/python3.12/copy.py", line 221, in _deepcopy_dict
    y[deepcopy(key, memo)] = deepcopy(value, memo)
                             ^^^^^^^^^^^^^^^^^^^^^
  File "/usr/local/lib/python3.12/copy.py", line 162, in deepcopy
    y = _reconstruct(x, memo, *rv)
        ^^^^^^^^^^^^^^^^^^^^^^^^^^
  File "/usr/local/lib/python3.12/copy.py", line 259, in _reconstruct
    state = deepcopy(state, memo)
            ^^^^^^^^^^^^^^^^^^^^^
  File "/usr/local/lib/python3.12/copy.py", line 136, in deepcopy
    y = copier(x, memo)
        ^^^^^^^^^^^^^^^
  File "/usr/local/lib/python3.12/copy.py", line 221, in _deepcopy_dict
    y[deepcopy(key, memo)] = deepcopy(value, memo)
                             ^^^^^^^^^^^^^^^^^^^^^
  File "/usr/local/lib/python3.12/copy.py", line 151, in deepcopy
    rv = reductor(4)
         ^^^^^^^^^^^
TypeError: cannot pickle '_thread.lock' object
[2025-04-29T03:13:38.805+0000] {local_task_job_runner.py:245} INFO - ::endgroup::
